INFO:apscheduler.scheduler:Adding job tentatively -- it will be properly scheduled when the scheduler starts
INFO:apscheduler.scheduler:Adding job tentatively -- it will be properly scheduled when the scheduler starts
INFO:src.utils:******************
INFO:src.utils:Database is ready!
INFO:src.utils:******************
INFO:mysql.connector:package: mysql.connector.plugins
INFO:mysql.connector:plugin_name: caching_sha2_password
INFO:mysql.connector:AUTHENTICATION_PLUGIN_CLASS: MySQLCachingSHA2PasswordAuthPlugin
INFO:src.utils:****************************************************************
INFO:src.utils:Creation Table successfully connected to MySQL database at 2025-01-08 12:38:09
INFO:src.utils:****************************************************************
INFO:src.utils:****************************
INFO:src.utils:Tables created successfully!
INFO:src.utils:****************************
INFO:apscheduler.scheduler:Added job "scan_url_call" to job store "default"
INFO:apscheduler.scheduler:Added job "availability_call" to job store "default"
INFO:apscheduler.scheduler:Scheduler started
INFO:apscheduler.executors.default:Running job "scan_url_call (trigger: interval[0:02:00], next run at: 2025-01-08 13:40:09 CET)" (scheduled at 2025-01-08 13:40:09.289464+01:00)
INFO:src.utils:*******************
INFO:src.utils:URL Scanner Started
INFO:src.utils:*******************
INFO:src.utils:****************************************************************
INFO:src.utils:URL Scanner successfully connected to MySQL database at 2025-01-08 12:40:10
INFO:src.utils:****************************************************************
ERROR:src.utils:----
ERROR:src.utils:Error retriving the Rating for: https://www.amazon.de/dp/8891250163 - Seraphim-Opus
ERROR:src.utils:----
INFO:src.utils:**************************************
INFO:src.utils:Image: https://m.media-amazon.com/images/I/61CQE1yP6FL._SY385_.jpg successfully downloaded!
INFO:src.utils:**************************************
INFO:src.utils:*****************************************************************
INFO:src.utils:JSON populated for URL https://www.amazon.de/dp/8891250163 Manga's ID: 2
INFO:src.utils:*****************************************************************
INFO:src.utils:*****************************************************************
INFO:src.utils:SQL Built for URL https://www.amazon.de/dp/8891250163 Manga's ID: 2
INFO:src.utils:*****************************************************************
INFO:src.utils:*****************************************************************
INFO:src.utils:Records added for Manga's ID:2 to the DB
INFO:src.utils:*****************************************************************
INFO:src.utils:*********************************************
INFO:src.utils:Url: https://www.amazon.de/dp/8891250163 with ID: 2 deleted from DB
INFO:src.utils:*********************************************
INFO:src.utils:**************************************
INFO:src.utils:Image: https://m.media-amazon.com/images/I/71rYEBQDFfL._SY385_.jpg successfully downloaded!
INFO:src.utils:**************************************
INFO:src.utils:*****************************************************************
INFO:src.utils:JSON populated for URL https://www.amazon.de/dp/8891290696 Manga's ID: 3
INFO:src.utils:*****************************************************************
INFO:src.utils:*****************************************************************
INFO:src.utils:SQL Built for URL https://www.amazon.de/dp/8891290696 Manga's ID: 3
INFO:src.utils:*****************************************************************
INFO:src.utils:*****************************************************************
INFO:src.utils:Records added for Manga's ID:3 to the DB
INFO:src.utils:*****************************************************************
INFO:src.utils:*********************************************
INFO:src.utils:Url: https://www.amazon.de/dp/8891290696 with ID: 3 deleted from DB
INFO:src.utils:*********************************************
INFO:src.utils:*******************
INFO:src.utils:All URLs processed.
INFO:src.utils:*******************
INFO:apscheduler.executors.default:Job "scan_url_call (trigger: interval[0:02:00], next run at: 2025-01-08 13:42:09 CET)" executed successfully
INFO:src.utils:****************************************************************
INFO:src.utils:List-all Route successfully connected to MySQL database at 2025-01-08 12:41:08
INFO:src.utils:****************************************************************
INFO:apscheduler.executors.default:Running job "availability_call (trigger: interval[0:03:00], next run at: 2025-01-08 13:44:09 CET)" (scheduled at 2025-01-08 13:41:09.289620+01:00)
INFO:src.utils:****************************
INFO:src.utils:Availability Scanner Started
INFO:src.utils:****************************
INFO:src.utils:****************************************************************
INFO:src.utils:Availability Check successfully connected to MySQL database at 2025-01-08 12:41:10
INFO:src.utils:****************************************************************
INFO:src.utils:************************
INFO:src.utils:Processing: 1 
INFO:src.utils:************************
INFO:src.utils:***********************************************
INFO:src.utils:Manga ID: 1 Is Available ... Skipping
INFO:src.utils:***********************************************
INFO:src.utils:************************
INFO:src.utils:Processing: 2 
INFO:src.utils:************************
WARNING:urllib3.connectionpool:Retrying (Retry(total=2, connect=None, read=None, redirect=None, status=None)) after connection broken by 'NewConnectionError('<urllib3.connection.HTTPConnection object at 0xffff7a59c610>: Failed to establish a new connection: [Errno 111] Connection refused')': /wd/hub/session/c250066f-6bcd-4e13-902d-2f98c05f13a8/execute/sync
WARNING:urllib3.connectionpool:Retrying (Retry(total=1, connect=None, read=None, redirect=None, status=None)) after connection broken by 'NewConnectionError('<urllib3.connection.HTTPConnection object at 0xffff7a5a1490>: Failed to establish a new connection: [Errno 111] Connection refused')': /wd/hub/session/c250066f-6bcd-4e13-902d-2f98c05f13a8/execute/sync
WARNING:urllib3.connectionpool:Retrying (Retry(total=0, connect=None, read=None, redirect=None, status=None)) after connection broken by 'NewConnectionError('<urllib3.connection.HTTPConnection object at 0xffff7a5a1e90>: Failed to establish a new connection: [Errno 111] Connection refused')': /wd/hub/session/c250066f-6bcd-4e13-902d-2f98c05f13a8/execute/sync
ERROR:src.utils:----
ERROR:src.utils:HTTPConnectionPool(host='selenium', port=4444): Max retries exceeded with url: /wd/hub/session/c250066f-6bcd-4e13-902d-2f98c05f13a8/execute/sync (Caused by NewConnectionError('<urllib3.connection.HTTPConnection object at 0xffff7a5a2890>: Failed to establish a new connection: [Errno 111] Connection refused'))
ERROR:src.utils:----
WARNING:urllib3.connectionpool:Retrying (Retry(total=2, connect=None, read=None, redirect=None, status=None)) after connection broken by 'NewConnectionError('<urllib3.connection.HTTPConnection object at 0xffff7a5a2f90>: Failed to establish a new connection: [Errno 111] Connection refused')': /wd/hub/session/c250066f-6bcd-4e13-902d-2f98c05f13a8
WARNING:urllib3.connectionpool:Retrying (Retry(total=1, connect=None, read=None, redirect=None, status=None)) after connection broken by 'NewConnectionError('<urllib3.connection.HTTPConnection object at 0xffff7a5a3590>: Failed to establish a new connection: [Errno 111] Connection refused')': /wd/hub/session/c250066f-6bcd-4e13-902d-2f98c05f13a8
WARNING:urllib3.connectionpool:Retrying (Retry(total=0, connect=None, read=None, redirect=None, status=None)) after connection broken by 'NewConnectionError('<urllib3.connection.HTTPConnection object at 0xffff7a5a3b50>: Failed to establish a new connection: [Errno 111] Connection refused')': /wd/hub/session/c250066f-6bcd-4e13-902d-2f98c05f13a8
ERROR:apscheduler.executors.default:Job "availability_call (trigger: interval[0:03:00], next run at: 2025-01-08 13:44:09 CET)" raised an exception
Traceback (most recent call last):
  File "/usr/local/lib/python3.11/site-packages/urllib3/connection.py", line 199, in _new_conn
    sock = connection.create_connection(
           ^^^^^^^^^^^^^^^^^^^^^^^^^^^^^
  File "/usr/local/lib/python3.11/site-packages/urllib3/util/connection.py", line 85, in create_connection
    raise err
  File "/usr/local/lib/python3.11/site-packages/urllib3/util/connection.py", line 73, in create_connection
    sock.connect(sa)
ConnectionRefusedError: [Errno 111] Connection refused

The above exception was the direct cause of the following exception:

Traceback (most recent call last):
  File "/usr/local/lib/python3.11/site-packages/urllib3/connectionpool.py", line 789, in urlopen
    response = self._make_request(
               ^^^^^^^^^^^^^^^^^^^
  File "/usr/local/lib/python3.11/site-packages/urllib3/connectionpool.py", line 495, in _make_request
    conn.request(
  File "/usr/local/lib/python3.11/site-packages/urllib3/connection.py", line 441, in request
    self.endheaders()
  File "/usr/local/lib/python3.11/http/client.py", line 1298, in endheaders
    self._send_output(message_body, encode_chunked=encode_chunked)
  File "/usr/local/lib/python3.11/http/client.py", line 1058, in _send_output
    self.send(msg)
  File "/usr/local/lib/python3.11/http/client.py", line 996, in send
    self.connect()
  File "/usr/local/lib/python3.11/site-packages/urllib3/connection.py", line 279, in connect
    self.sock = self._new_conn()
                ^^^^^^^^^^^^^^^^
  File "/usr/local/lib/python3.11/site-packages/urllib3/connection.py", line 214, in _new_conn
    raise NewConnectionError(
urllib3.exceptions.NewConnectionError: <urllib3.connection.HTTPConnection object at 0xffff7a5ac250>: Failed to establish a new connection: [Errno 111] Connection refused

The above exception was the direct cause of the following exception:

Traceback (most recent call last):
  File "/usr/local/lib/python3.11/site-packages/apscheduler/executors/base.py", line 131, in run_job
    retval = job.func(*job.args, **job.kwargs)
             ^^^^^^^^^^^^^^^^^^^^^^^^^^^^^^^^^
  File "/app/src/utils.py", line 490, in availability_call
  File "/usr/local/lib/python3.11/site-packages/selenium/webdriver/remote/webdriver.py", line 502, in quit
    self.execute(Command.QUIT)
  File "/usr/local/lib/python3.11/site-packages/selenium/webdriver/remote/webdriver.py", line 378, in execute
    response = self.command_executor.execute(driver_command, params)
               ^^^^^^^^^^^^^^^^^^^^^^^^^^^^^^^^^^^^^^^^^^^^^^^^^^^^^
  File "/usr/local/lib/python3.11/site-packages/selenium/webdriver/remote/remote_connection.py", line 391, in execute
    return self._request(command_info[0], url, body=data)
           ^^^^^^^^^^^^^^^^^^^^^^^^^^^^^^^^^^^^^^^^^^^^^^
  File "/usr/local/lib/python3.11/site-packages/selenium/webdriver/remote/remote_connection.py", line 415, in _request
    response = self._conn.request(method, url, body=body, headers=headers, timeout=self._client_config.timeout)
               ^^^^^^^^^^^^^^^^^^^^^^^^^^^^^^^^^^^^^^^^^^^^^^^^^^^^^^^^^^^^^^^^^^^^^^^^^^^^^^^^^^^^^^^^^^^^^^^^
  File "/usr/local/lib/python3.11/site-packages/urllib3/_request_methods.py", line 135, in request
    return self.request_encode_url(
           ^^^^^^^^^^^^^^^^^^^^^^^^
  File "/usr/local/lib/python3.11/site-packages/urllib3/_request_methods.py", line 182, in request_encode_url
    return self.urlopen(method, url, **extra_kw)
           ^^^^^^^^^^^^^^^^^^^^^^^^^^^^^^^^^^^^^
  File "/usr/local/lib/python3.11/site-packages/urllib3/poolmanager.py", line 443, in urlopen
    response = conn.urlopen(method, u.request_uri, **kw)
               ^^^^^^^^^^^^^^^^^^^^^^^^^^^^^^^^^^^^^^^^^
  File "/usr/local/lib/python3.11/site-packages/urllib3/connectionpool.py", line 873, in urlopen
    return self.urlopen(
           ^^^^^^^^^^^^^
  File "/usr/local/lib/python3.11/site-packages/urllib3/connectionpool.py", line 873, in urlopen
    return self.urlopen(
           ^^^^^^^^^^^^^
  File "/usr/local/lib/python3.11/site-packages/urllib3/connectionpool.py", line 873, in urlopen
    return self.urlopen(
           ^^^^^^^^^^^^^
  File "/usr/local/lib/python3.11/site-packages/urllib3/connectionpool.py", line 843, in urlopen
    retries = retries.increment(
              ^^^^^^^^^^^^^^^^^^
  File "/usr/local/lib/python3.11/site-packages/urllib3/util/retry.py", line 519, in increment
    raise MaxRetryError(_pool, url, reason) from reason  # type: ignore[arg-type]
    ^^^^^^^^^^^^^^^^^^^^^^^^^^^^^^^^^^^^^^^^^^^^^^^^^^^
urllib3.exceptions.MaxRetryError: HTTPConnectionPool(host='selenium', port=4444): Max retries exceeded with url: /wd/hub/session/c250066f-6bcd-4e13-902d-2f98c05f13a8 (Caused by NewConnectionError('<urllib3.connection.HTTPConnection object at 0xffff7a5ac250>: Failed to establish a new connection: [Errno 111] Connection refused'))
INFO:apscheduler.scheduler:Scheduler has been shut down
